2018-08-05 17:30:31,377 Exception on /edit_profile [GET] [in c:\users\kurt\appdata\local\programs\python\python37\lib\site-packages\flask\app.py:1761]
Traceback (most recent call last):
  File "c:\users\kurt\appdata\local\programs\python\python37\lib\site-packages\flask\app.py", line 2292, in wsgi_app
    response = self.full_dispatch_request()
  File "c:\users\kurt\appdata\local\programs\python\python37\lib\site-packages\flask\app.py", line 1815, in full_dispatch_request
    rv = self.handle_user_exception(e)
  File "c:\users\kurt\appdata\local\programs\python\python37\lib\site-packages\flask\app.py", line 1718, in handle_user_exception
    reraise(exc_type, exc_value, tb)
  File "c:\users\kurt\appdata\local\programs\python\python37\lib\site-packages\flask\_compat.py", line 35, in reraise
    raise value
  File "c:\users\kurt\appdata\local\programs\python\python37\lib\site-packages\flask\app.py", line 1813, in full_dispatch_request
    rv = self.dispatch_request()
  File "c:\users\kurt\appdata\local\programs\python\python37\lib\site-packages\flask\app.py", line 1799, in dispatch_request
    return self.view_functions[rule.endpoint](**req.view_args)
  File "c:\users\kurt\appdata\local\programs\python\python37\lib\site-packages\flask_login\utils.py", line 261, in decorated_view
    return func(*args, **kwargs)
  File "C:\Users\kurt\Python\kurtain\kurtain\routes.py", line 80, in edit_profile
    return render_template('user.html', title='Profile', form=form)
  File "c:\users\kurt\appdata\local\programs\python\python37\lib\site-packages\flask\templating.py", line 135, in render_template
    context, ctx.app)
  File "c:\users\kurt\appdata\local\programs\python\python37\lib\site-packages\flask\templating.py", line 117, in _render
    rv = template.render(context)
  File "c:\users\kurt\appdata\local\programs\python\python37\lib\site-packages\jinja2\asyncsupport.py", line 76, in render
    return original_render(self, *args, **kwargs)
  File "c:\users\kurt\appdata\local\programs\python\python37\lib\site-packages\jinja2\environment.py", line 1008, in render
    return self.environment.handle_exception(exc_info, True)
  File "c:\users\kurt\appdata\local\programs\python\python37\lib\site-packages\jinja2\environment.py", line 780, in handle_exception
    reraise(exc_type, exc_value, tb)
  File "c:\users\kurt\appdata\local\programs\python\python37\lib\site-packages\jinja2\_compat.py", line 37, in reraise
    raise value.with_traceback(tb)
  File "C:\Users\kurt\Python\kurtain\kurtain\templates\user.html", line 1, in top-level template code
    {% extends "base.html" %}
  File "C:\Users\kurt\Python\kurtain\kurtain\templates\base.html", line 43, in top-level template code
    {% block content %}{% endblock %}
  File "C:\Users\kurt\Python\kurtain\kurtain\templates\user.html", line 6, in block "content"
    <td><img src="{{ user.avatar(128) }}"></td>
  File "c:\users\kurt\appdata\local\programs\python\python37\lib\site-packages\jinja2\environment.py", line 430, in getattr
    return getattr(obj, attribute)
jinja2.exceptions.UndefinedError: 'user' is undefined
2018-08-05 17:31:31,585 Kurtain Startup [in C:\Users\kurt\Python\kurtain\kurtain\__init__.py:42]
2018-08-05 17:31:44,882 Exception on /edit_profile [POST] [in c:\users\kurt\appdata\local\programs\python\python37\lib\site-packages\flask\app.py:1761]
Traceback (most recent call last):
  File "c:\users\kurt\appdata\local\programs\python\python37\lib\site-packages\flask\app.py", line 2292, in wsgi_app
    response = self.full_dispatch_request()
  File "c:\users\kurt\appdata\local\programs\python\python37\lib\site-packages\flask\app.py", line 1815, in full_dispatch_request
    rv = self.handle_user_exception(e)
  File "c:\users\kurt\appdata\local\programs\python\python37\lib\site-packages\flask\app.py", line 1718, in handle_user_exception
    reraise(exc_type, exc_value, tb)
  File "c:\users\kurt\appdata\local\programs\python\python37\lib\site-packages\flask\_compat.py", line 35, in reraise
    raise value
  File "c:\users\kurt\appdata\local\programs\python\python37\lib\site-packages\flask\app.py", line 1813, in full_dispatch_request
    rv = self.dispatch_request()
  File "c:\users\kurt\appdata\local\programs\python\python37\lib\site-packages\flask\app.py", line 1799, in dispatch_request
    return self.view_functions[rule.endpoint](**req.view_args)
  File "c:\users\kurt\appdata\local\programs\python\python37\lib\site-packages\flask_login\utils.py", line 261, in decorated_view
    return func(*args, **kwargs)
  File "C:\Users\kurt\Python\kurtain\kurtain\routes.py", line 76, in edit_profile
    return redirect(url_for('user', username = username))
NameError: name 'username' is not defined
2018-08-05 17:32:03,132 Exception on /edit_profile [POST] [in c:\users\kurt\appdata\local\programs\python\python37\lib\site-packages\flask\app.py:1761]
Traceback (most recent call last):
  File "c:\users\kurt\appdata\local\programs\python\python37\lib\site-packages\flask\app.py", line 2292, in wsgi_app
    response = self.full_dispatch_request()
  File "c:\users\kurt\appdata\local\programs\python\python37\lib\site-packages\flask\app.py", line 1815, in full_dispatch_request
    rv = self.handle_user_exception(e)
  File "c:\users\kurt\appdata\local\programs\python\python37\lib\site-packages\flask\app.py", line 1718, in handle_user_exception
    reraise(exc_type, exc_value, tb)
  File "c:\users\kurt\appdata\local\programs\python\python37\lib\site-packages\flask\_compat.py", line 35, in reraise
    raise value
  File "c:\users\kurt\appdata\local\programs\python\python37\lib\site-packages\flask\app.py", line 1813, in full_dispatch_request
    rv = self.dispatch_request()
  File "c:\users\kurt\appdata\local\programs\python\python37\lib\site-packages\flask\app.py", line 1799, in dispatch_request
    return self.view_functions[rule.endpoint](**req.view_args)
  File "c:\users\kurt\appdata\local\programs\python\python37\lib\site-packages\flask_login\utils.py", line 261, in decorated_view
    return func(*args, **kwargs)
  File "C:\Users\kurt\Python\kurtain\kurtain\routes.py", line 76, in edit_profile
    return redirect(url_for('user', username = username))
NameError: name 'username' is not defined
2018-08-05 17:37:48,046 Kurtain Startup [in C:\Users\kurt\Python\kurtain\kurtain\__init__.py:42]
2018-08-05 17:40:28,179 Kurtain Startup [in C:\Users\kurt\Python\kurtain\kurtain\__init__.py:42]
2018-08-05 17:53:25,217 Kurtain Startup [in C:\Users\kurt\Python\kurtain\kurtain\__init__.py:42]
2018-08-05 17:59:25,243 Kurtain Startup [in C:\Users\kurt\Python\kurtain\kurtain\__init__.py:42]
2018-08-05 17:59:36,232 Exception on /edit_profile [POST] [in c:\users\kurt\appdata\local\programs\python\python37\lib\site-packages\flask\app.py:1761]
Traceback (most recent call last):
  File "c:\users\kurt\appdata\local\programs\python\python37\lib\site-packages\flask\app.py", line 2292, in wsgi_app
    response = self.full_dispatch_request()
  File "c:\users\kurt\appdata\local\programs\python\python37\lib\site-packages\flask\app.py", line 1815, in full_dispatch_request
    rv = self.handle_user_exception(e)
  File "c:\users\kurt\appdata\local\programs\python\python37\lib\site-packages\flask\app.py", line 1718, in handle_user_exception
    reraise(exc_type, exc_value, tb)
  File "c:\users\kurt\appdata\local\programs\python\python37\lib\site-packages\flask\_compat.py", line 35, in reraise
    raise value
  File "c:\users\kurt\appdata\local\programs\python\python37\lib\site-packages\flask\app.py", line 1813, in full_dispatch_request
    rv = self.dispatch_request()
  File "c:\users\kurt\appdata\local\programs\python\python37\lib\site-packages\flask\app.py", line 1799, in dispatch_request
    return self.view_functions[rule.endpoint](**req.view_args)
  File "c:\users\kurt\appdata\local\programs\python\python37\lib\site-packages\flask_login\utils.py", line 261, in decorated_view
    return func(*args, **kwargs)
  File "C:\Users\kurt\Python\kurtain\kurtain\routes.py", line 76, in edit_profile
    return redirect(url_for('user', username = username))
NameError: name 'username' is not defined
2018-08-05 18:02:06,775 Kurtain Startup [in C:\Users\kurt\Python\kurtain\kurtain\__init__.py:42]
2018-08-05 18:02:11,649 Exception on /edit_profile [POST] [in c:\users\kurt\appdata\local\programs\python\python37\lib\site-packages\flask\app.py:1761]
Traceback (most recent call last):
  File "c:\users\kurt\appdata\local\programs\python\python37\lib\site-packages\flask\app.py", line 2292, in wsgi_app
    response = self.full_dispatch_request()
  File "c:\users\kurt\appdata\local\programs\python\python37\lib\site-packages\flask\app.py", line 1815, in full_dispatch_request
    rv = self.handle_user_exception(e)
  File "c:\users\kurt\appdata\local\programs\python\python37\lib\site-packages\flask\app.py", line 1718, in handle_user_exception
    reraise(exc_type, exc_value, tb)
  File "c:\users\kurt\appdata\local\programs\python\python37\lib\site-packages\flask\_compat.py", line 35, in reraise
    raise value
  File "c:\users\kurt\appdata\local\programs\python\python37\lib\site-packages\flask\app.py", line 1813, in full_dispatch_request
    rv = self.dispatch_request()
  File "c:\users\kurt\appdata\local\programs\python\python37\lib\site-packages\flask\app.py", line 1799, in dispatch_request
    return self.view_functions[rule.endpoint](**req.view_args)
  File "c:\users\kurt\appdata\local\programs\python\python37\lib\site-packages\flask_login\utils.py", line 261, in decorated_view
    return func(*args, **kwargs)
  File "C:\Users\kurt\Python\kurtain\kurtain\routes.py", line 76, in edit_profile
    return redirect(url_for('user', username = username))
NameError: name 'username' is not defined
2018-08-05 18:04:44,954 Kurtain Startup [in C:\Users\kurt\Python\kurtain\kurtain\__init__.py:42]
2018-08-05 18:06:12,220 Kurtain Startup [in C:\Users\kurt\Python\kurtain\kurtain\__init__.py:42]
