2018-08-03 15:17:48,123 Kurtain Startup [in C:\Users\kurt\Python\kurtain\kurtain\__init__.py:42]
2018-08-03 15:17:54,573 Exception on /edit_profile [POST] [in c:\users\kurt\appdata\local\programs\python\python37\lib\site-packages\flask\app.py:1761]
Traceback (most recent call last):
  File "c:\users\kurt\appdata\local\programs\python\python37\lib\site-packages\sqlalchemy\engine\base.py", line 1193, in _execute_context
    context)
  File "c:\users\kurt\appdata\local\programs\python\python37\lib\site-packages\sqlalchemy\engine\default.py", line 509, in do_execute
    cursor.execute(statement, parameters)
sqlite3.IntegrityError: UNIQUE constraint failed: user.username

The above exception was the direct cause of the following exception:

Traceback (most recent call last):
  File "c:\users\kurt\appdata\local\programs\python\python37\lib\site-packages\flask\app.py", line 2292, in wsgi_app
    response = self.full_dispatch_request()
  File "c:\users\kurt\appdata\local\programs\python\python37\lib\site-packages\flask\app.py", line 1815, in full_dispatch_request
    rv = self.handle_user_exception(e)
  File "c:\users\kurt\appdata\local\programs\python\python37\lib\site-packages\flask\app.py", line 1718, in handle_user_exception
    reraise(exc_type, exc_value, tb)
  File "c:\users\kurt\appdata\local\programs\python\python37\lib\site-packages\flask\_compat.py", line 35, in reraise
    raise value
  File "c:\users\kurt\appdata\local\programs\python\python37\lib\site-packages\flask\app.py", line 1813, in full_dispatch_request
    rv = self.dispatch_request()
  File "c:\users\kurt\appdata\local\programs\python\python37\lib\site-packages\flask\app.py", line 1799, in dispatch_request
    return self.view_functions[rule.endpoint](**req.view_args)
  File "c:\users\kurt\appdata\local\programs\python\python37\lib\site-packages\flask_login\utils.py", line 261, in decorated_view
    return func(*args, **kwargs)
  File "C:\Users\kurt\Python\kurtain\kurtain\routes.py", line 74, in edit_profile
    db.session.commit()
  File "c:\users\kurt\appdata\local\programs\python\python37\lib\site-packages\sqlalchemy\orm\scoping.py", line 153, in do
    return getattr(self.registry(), name)(*args, **kwargs)
  File "c:\users\kurt\appdata\local\programs\python\python37\lib\site-packages\sqlalchemy\orm\session.py", line 943, in commit
    self.transaction.commit()
  File "c:\users\kurt\appdata\local\programs\python\python37\lib\site-packages\sqlalchemy\orm\session.py", line 467, in commit
    self._prepare_impl()
  File "c:\users\kurt\appdata\local\programs\python\python37\lib\site-packages\sqlalchemy\orm\session.py", line 447, in _prepare_impl
    self.session.flush()
  File "c:\users\kurt\appdata\local\programs\python\python37\lib\site-packages\sqlalchemy\orm\session.py", line 2254, in flush
    self._flush(objects)
  File "c:\users\kurt\appdata\local\programs\python\python37\lib\site-packages\sqlalchemy\orm\session.py", line 2380, in _flush
    transaction.rollback(_capture_exception=True)
  File "c:\users\kurt\appdata\local\programs\python\python37\lib\site-packages\sqlalchemy\util\langhelpers.py", line 66, in __exit__
    compat.reraise(exc_type, exc_value, exc_tb)
  File "c:\users\kurt\appdata\local\programs\python\python37\lib\site-packages\sqlalchemy\util\compat.py", line 249, in reraise
    raise value
  File "c:\users\kurt\appdata\local\programs\python\python37\lib\site-packages\sqlalchemy\orm\session.py", line 2344, in _flush
    flush_context.execute()
  File "c:\users\kurt\appdata\local\programs\python\python37\lib\site-packages\sqlalchemy\orm\unitofwork.py", line 391, in execute
    rec.execute(self)
  File "c:\users\kurt\appdata\local\programs\python\python37\lib\site-packages\sqlalchemy\orm\unitofwork.py", line 556, in execute
    uow
  File "c:\users\kurt\appdata\local\programs\python\python37\lib\site-packages\sqlalchemy\orm\persistence.py", line 177, in save_obj
    mapper, table, update)
  File "c:\users\kurt\appdata\local\programs\python\python37\lib\site-packages\sqlalchemy\orm\persistence.py", line 768, in _emit_update_statements
    execute(statement, multiparams)
  File "c:\users\kurt\appdata\local\programs\python\python37\lib\site-packages\sqlalchemy\engine\base.py", line 948, in execute
    return meth(self, multiparams, params)
  File "c:\users\kurt\appdata\local\programs\python\python37\lib\site-packages\sqlalchemy\sql\elements.py", line 269, in _execute_on_connection
    return connection._execute_clauseelement(self, multiparams, params)
  File "c:\users\kurt\appdata\local\programs\python\python37\lib\site-packages\sqlalchemy\engine\base.py", line 1060, in _execute_clauseelement
    compiled_sql, distilled_params
  File "c:\users\kurt\appdata\local\programs\python\python37\lib\site-packages\sqlalchemy\engine\base.py", line 1200, in _execute_context
    context)
  File "c:\users\kurt\appdata\local\programs\python\python37\lib\site-packages\sqlalchemy\engine\base.py", line 1413, in _handle_dbapi_exception
    exc_info
  File "c:\users\kurt\appdata\local\programs\python\python37\lib\site-packages\sqlalchemy\util\compat.py", line 265, in raise_from_cause
    reraise(type(exception), exception, tb=exc_tb, cause=cause)
  File "c:\users\kurt\appdata\local\programs\python\python37\lib\site-packages\sqlalchemy\util\compat.py", line 248, in reraise
    raise value.with_traceback(tb)
  File "c:\users\kurt\appdata\local\programs\python\python37\lib\site-packages\sqlalchemy\engine\base.py", line 1193, in _execute_context
    context)
  File "c:\users\kurt\appdata\local\programs\python\python37\lib\site-packages\sqlalchemy\engine\default.py", line 509, in do_execute
    cursor.execute(statement, parameters)
sqlalchemy.exc.IntegrityError: (sqlite3.IntegrityError) UNIQUE constraint failed: user.username [SQL: 'UPDATE user SET username=?, about_me=? WHERE user.id = ?'] [parameters: ('susan', 'jag är kurt', 2)] (Background on this error at: http://sqlalche.me/e/gkpj)
2018-08-03 15:23:27,213 Kurtain Startup [in C:\Users\kurt\Python\kurtain\kurtain\__init__.py:42]
2018-08-03 15:23:32,887 Exception on /edit_profile [GET] [in c:\users\kurt\appdata\local\programs\python\python37\lib\site-packages\flask\app.py:1761]
Traceback (most recent call last):
  File "c:\users\kurt\appdata\local\programs\python\python37\lib\site-packages\flask\app.py", line 2292, in wsgi_app
    response = self.full_dispatch_request()
  File "c:\users\kurt\appdata\local\programs\python\python37\lib\site-packages\flask\app.py", line 1815, in full_dispatch_request
    rv = self.handle_user_exception(e)
  File "c:\users\kurt\appdata\local\programs\python\python37\lib\site-packages\flask\app.py", line 1718, in handle_user_exception
    reraise(exc_type, exc_value, tb)
  File "c:\users\kurt\appdata\local\programs\python\python37\lib\site-packages\flask\_compat.py", line 35, in reraise
    raise value
  File "c:\users\kurt\appdata\local\programs\python\python37\lib\site-packages\flask\app.py", line 1813, in full_dispatch_request
    rv = self.dispatch_request()
  File "c:\users\kurt\appdata\local\programs\python\python37\lib\site-packages\flask\app.py", line 1799, in dispatch_request
    return self.view_functions[rule.endpoint](**req.view_args)
  File "c:\users\kurt\appdata\local\programs\python\python37\lib\site-packages\flask_login\utils.py", line 261, in decorated_view
    return func(*args, **kwargs)
  File "C:\Users\kurt\Python\kurtain\kurtain\routes.py", line 70, in edit_profile
    form = EditProfileForm(current_user.username)
  File "c:\users\kurt\appdata\local\programs\python\python37\lib\site-packages\wtforms\form.py", line 212, in __call__
    return type.__call__(cls, *args, **kwargs)
  File "C:\Users\kurt\Python\kurtain\kurtain\forms.py", line 35, in __init__
    super(editProfileForm, self).__init__(*args, **kwargs)
NameError: name 'editProfileForm' is not defined
2018-08-03 15:23:38,480 Exception on /edit_profile [GET] [in c:\users\kurt\appdata\local\programs\python\python37\lib\site-packages\flask\app.py:1761]
Traceback (most recent call last):
  File "c:\users\kurt\appdata\local\programs\python\python37\lib\site-packages\flask\app.py", line 2292, in wsgi_app
    response = self.full_dispatch_request()
  File "c:\users\kurt\appdata\local\programs\python\python37\lib\site-packages\flask\app.py", line 1815, in full_dispatch_request
    rv = self.handle_user_exception(e)
  File "c:\users\kurt\appdata\local\programs\python\python37\lib\site-packages\flask\app.py", line 1718, in handle_user_exception
    reraise(exc_type, exc_value, tb)
  File "c:\users\kurt\appdata\local\programs\python\python37\lib\site-packages\flask\_compat.py", line 35, in reraise
    raise value
  File "c:\users\kurt\appdata\local\programs\python\python37\lib\site-packages\flask\app.py", line 1813, in full_dispatch_request
    rv = self.dispatch_request()
  File "c:\users\kurt\appdata\local\programs\python\python37\lib\site-packages\flask\app.py", line 1799, in dispatch_request
    return self.view_functions[rule.endpoint](**req.view_args)
  File "c:\users\kurt\appdata\local\programs\python\python37\lib\site-packages\flask_login\utils.py", line 261, in decorated_view
    return func(*args, **kwargs)
  File "C:\Users\kurt\Python\kurtain\kurtain\routes.py", line 70, in edit_profile
    form = EditProfileForm(current_user.username)
  File "c:\users\kurt\appdata\local\programs\python\python37\lib\site-packages\wtforms\form.py", line 212, in __call__
    return type.__call__(cls, *args, **kwargs)
  File "C:\Users\kurt\Python\kurtain\kurtain\forms.py", line 35, in __init__
    super(editProfileForm, self).__init__(*args, **kwargs)
NameError: name 'editProfileForm' is not defined
2018-08-03 15:24:34,194 Kurtain Startup [in C:\Users\kurt\Python\kurtain\kurtain\__init__.py:42]
2018-08-03 15:25:15,270 Kurtain Startup [in C:\Users\kurt\Python\kurtain\kurtain\__init__.py:42]
2018-08-05 16:32:35,478 Kurtain Startup [in C:\Users\kurt\Python\kurtain\kurtain\__init__.py:42]
2018-08-05 16:32:57,816 Kurtain Startup [in C:\Users\kurt\Python\kurtain\kurtain\__init__.py:42]
